Workbook
Name Slicer_Employee_Type: #N/A
Name Slicer_Gender: #N/A
Name Slicer_Join_Month: #N/A
Name Slicer_Working_status: #N/A
Name Slicer_Years__Date_of_Join: #N/A

Sheet Main DashBoard
P58: =GETPIVOTDATA("SL",Master_Pivot!$B$11) -> 409 | R58: =GETPIVOTDATA("SL",Master_Pivot!$B$15,"Working status","Active") -> 407 | T58: =GETPIVOTDATA("SL",Master_Pivot!$B$15,"Working status","Fire") -> 1
T59: =GETPIVOTDATA("SL",Master_Pivot!$B$15,"Working status","Resigned") -> 1
Q60: =GETPIVOTDATA("Basic Salary",Master_Pivot!$B$23) -> 6532800
R61: =GETPIVOTDATA("Basic Salary",Master_Pivot!$B$27) -> 16011.765

Sheet Workforce Composition
P58: =GETPIVOTDATA("SL",Master_Pivot!$B$11) -> 409 | R58: =GETPIVOTDATA("SL",Master_Pivot!$B$15,"Working status","Active") -> 407 | T58: =GETPIVOTDATA("SL",Master_Pivot!$B$15,"Working status","Fire") -> 1
T59: =GETPIVOTDATA("SL",Master_Pivot!$B$15,"Working status","Resigned") -> 1
Q60: =GETPIVOTDATA("Basic Salary",Master_Pivot!$B$23) -> 6532800
R61: =GETPIVOTDATA("Basic Salary",Master_Pivot!$B$27) -> 16011.765
J70: =GETPIVOTDATA("[__Xl2].[Measures].[Count of SL]",Master_Pivot!$F$11,"[tblHR].[Employee Category]","[tblHR].[Employee Category].&[Direct]")*100 -> 92.420538 | L70: =Master_Pivot!DD18 -> 0.33740831
J71: =GETPIVOTDATA("[Measures].[Distinct Count of Designation]",Master_Pivot!$CY$3) -> 10
J72: =Master_Pivot!$CZ$18 -> 0.053789731
J73: =GETPIVOTDATA("[__Xl2].[Measures].[Count of Employee Type]",Master_Pivot!$DB$17,"[tblHR].[Gender]","[tblHR].[Gender].&[Female]") -> 0.33740831
J74: {=Master_Pivot!DD18:DD19} -> 0.33740831
J75: 0.66259169

Sheet Salary & Financial Analysis
P58: =GETPIVOTDATA("SL",Master_Pivot!$B$11) -> 409 | R58: =GETPIVOTDATA("SL",Master_Pivot!$B$15,"Working status","Active") -> 407 | T58: =GETPIVOTDATA("SL",Master_Pivot!$B$15,"Working status","Fire") -> 1
T59: =GETPIVOTDATA("SL",Master_Pivot!$B$15,"Working status","Resigned") -> 1
Q60: =GETPIVOTDATA("Basic Salary",Master_Pivot!$B$23) -> 6532800
R61: =GETPIVOTDATA("Basic Salary",Master_Pivot!$B$27) -> 16011.765

Sheet Dashboard_Auto

Sheet Pivot_Auto

Sheet adfadfa

Sheet Dashboard

Sheet Sheet1

Sheet Master_Pivot
A3: Row Labels | B3: Employees Count | E3: Row Labels | F3: Employees Count | I3: Row Labels | J3: Employees Count | M3: Employees Count | P3: Employees Count | S3: Total Payroll | U3: Row Labels | V3: Employees Count | Y3: Average Salary | AB3: Count of SL | AC3: Column Labels | AG3: Row Labels | AH3: Count of SL | AJ3: Row Labels | AK3: Count of SL | AN3: Row Labels | AO3: Employees Count | AR3: Row Labels | AS3: Average Salary | AV3: Row Labels | AW3: Employees Count | AZ3: Active Employees | BC3: Row Labels | BD3: Employees Count | BG3: Count of SL | BH3: Column Labels | BM3: Row Labels | BN3: Count of SL | BQ3: Row Labels | BR3: Count of SL | BT3: Row Labels | BU3: Average of Basic Salary | BX3: Row Labels | BY3: Sum of SL | CL3: no.of.department | CY3: Row Labels | CZ3: Distinct Count of Designation | DA3: Count of Designation
A4: 1km -3km | B4: 17 | E4: A+ | F4: 3 | I4: Female | J4: 1 | M4: 21 | P4: 21 | S4: 370626 | U4: Aug-23 | V4: 2 | Y4: 18531.3 | AB4: Row Labels | AC4: Female | AD4: Male | AE4: Grand Total | AG4: Female | AH4: 138 | AJ4: Female | AK4: 138 | AN4: Active | AO4: 21 | AR4: Permanent | AS4: 18531.3 | AV4: Married | AW4: 12 | AZ4: 21 | BC4: Active | BD4: 20 | BG4: Row Labels | BH4: Female | BI4: Male | BJ4: Grand Total | BM4: Direct | BN4: 378 | BQ4: Active | BR4: 407 | BT4: Assistant Leader | BU4: 12600 | BX4: A- | BY4: 488 | CB4: Row Labels | CC4: Count of SL | CL4: =COUNTA(_xlfn.UNIQUE(tblHR[[#All],[Department]])) -> 8 | CU4: Row Labels | CV4: Distinct Count of Department | CW4: Count of Department | CY4: Assistant Leader | CZ4: 1 | DA4: 5
A5: 3km-5km | B5: 3 | E5: AB+ | F5: 3 | I5: Male | J5: 20 | U5: Basic Salary | V5: 1 | AB5: Administration Dept. | AC5: 1 | AD5: 3 | AE5: 4 | AG5: Male | AH5: 271 | AJ5: Male | AK5: 271 | AV5: Single | AW5: 9 | BC5: Join Month | BD5: 1 | BG5: Assistant Leader | BI5: 5 | BJ5: 5 | BM5: InDirect | BN5: 24 | BQ5: Fire | BR5: 1 | BT5: Assistant Manager | BU5: 12500 | BX5: A+ | BY5: 18348 | CB5: Married | CC5: 69 | CU5: Administration Dept. | CV5: 1 | CW5: 4 | CY5: Assistant Manager | CZ5: 1 | DA5: 2
A6: 5-10km | B6: 1 | E6: B+ | F6: 6 | U6: Jul-23 | V6: 11 | AB6: Human Resource Dept. | AC6: 1 | AE6: 1 | AG6: Grand Total | AH6: 409 | AJ6: Grand Total | AK6: 409 | BG6: Assistant Manager | BI6: 2 | BJ6: 2 | BM6: Management | BN6: 7 | BQ6: Resigned | BR6: 1 | BT6: Cleaner | BU6: 30000 | BX6: AB- | BY6: 635 | CB6: Single | CC6: 340 | CK6: Column Labels | CU6: Human Resource Dept. | CV6: 1 | CW6: 1 | CY6: Cleaner | CZ6: 1 | DA6: 2
E7: O+ | F7: 9 | U7: Jun-23 | V7: 6 | AB7: Packing Dept. | AC7: 32 | AD7: 61 | AE7: 93 | BG7: Cleaner | BI7: 2 | BJ7: 2 | BM7: Grand Total | BN7: 409 | BQ7: Grand Total | BR7: 409 | BT7: Executive | BU7: 5653.9333 | BX7: AB+ | BY7: 6728 | CB7: Grand Total | CC7: 409 | CK7: Administration Dept. | CL7: Human Resource Dept. | CM7: Packing Dept. | CN7: PMC & Warehouse Dept. | CO7: Product Engineering | CP7: Production Dept. | CQ7: Quality Dept. | CR7: Grand Total | CU7: Packing Dept. | CV7: 1 | CW7: 93 | CY7: Executive | CZ7: 1 | DA7: 15
U8: Sep-23 | V8: 1 | AB8: PMC & Warehouse Dept. | AC8: 5 | AD8: 23 | AE8: 28 | BG8: Executive | BH8: 5 | BI8: 10 | BJ8: 15 | BT8: Line Leader | BU8: 10363.636 | BX8: B- | BY8: 1180 | CJ8: Count of SL | CK8: 4 | CL8: 1 | CM8: 93 | CN8: 28 | CO8: 3 | CP8: 154 | CQ8: 126 | CR8: 409 | CU8: PMC & Warehouse Dept. | CV8: 1 | CW8: 28 | CY8: Line Leader | CZ8: 1 | DA8: 11
AB9: Product Engineering | AD9: 3 | AE9: 3 | BG9: Line Leader | BH9: 1 | BI9: 10 | BJ9: 11 | BT9: Line Operator | BU9: 16767.138 | BX9: B+ | BY9: 26260 | CU9: Product Engineering | CV9: 1 | CW9: 3 | CY9: Line Operator | CZ9: 1 | DA9: 363 | DR9: Working status | DS9: Active
AB10: Production Dept. | AC10: 53 | AD10: 101 | AE10: 154 | BG10: Line Operator | BH10: 130 | BI10: 233 | BJ10: 363 | BT10: Loader | BU10: 10000 | BX10: N/A | BY10: 6343 | CU10: Production Dept. | CV10: 1 | CW10: 154 | CY10: Loader | CZ10: 1 | DA10: 2
B11: Total Employees | F11: Row Labels | G11: Count of SL | H11: Count of SL2 | AB11: Quality Dept. | AC11: 46 | AD11: 80 | AE11: 126 | BG11: Loader | BI11: 2 | BJ11: 2 | BT11: Manager | BU11: 9057.4 | BX11: O- | BY11: 863 | CU11: Quality Dept. | CV11: 1 | CW11: 126 | CY11: Manager | CZ11: 1 | DA11: 5 | DR11: Row Labels | DS11: Count of ID
B12: 409 | F12: Direct | G12: 378 | H12: 0.92420538 | AB12: Grand Total | AC12: 138 | AD12: 271 | AE12: 409 | BG12: Manager | BH12: 2 | BI12: 3 | BJ12: 5 | BT12: Senior Eecutive | BU12: 7000 | BX12: O+ | BY12: 23000 | CU12: Grand Total | CV12: 7 | CW12: 409 | CY12: Senior Eecutive | CZ12: 1 | DA12: 3 | DR12: Administration Dept. | DS12: 3
F13: InDirect | G13: 24 | H13: 0.058679707 | BG13: Senior Eecutive | BI13: 3 | BJ13: 3 | BT13: Support Staff | BU13: 30000 | BX13: Grand Total | BY13: 83845 | CY13: Support Staff | CZ13: 1 | DA13: 1 | DR13: Human Resource Dept. | DS13: 1 | ED13: Years (Date of Join) | EE13: 2023
F14: Management | G14: 7 | H14: 0.017114914 | BG14: Support Staff | BI14: 1 | BJ14: 1 | BT14: Grand Total | BU14: 16011.765 | CU14: Row Labels | CV14: Count of Employee Category | CY14: Grand Total | CZ14: 10 | DA14: 409 | DR14: Packing Dept. | DS14: 93
B15: Row Labels | C15: Total Employees | F15: Grand Total | G15: 409 | H15: 1 | BG15: Grand Total | BH15: 138 | BI15: 271 | BJ15: 409 | CU15: Direct | CV15: 378 | DR15: PMC & Warehouse Dept. | DS15: 28 | ED15: Average of Baisc Salary | EE15: Column Labels
B16: Active | C16: 407 | CU16: InDirect | CV16: 24 | DR16: Product Engineering | DS16: 3 | ED16: Row Labels | EE16: Diract | EF16: Indiract | EG16: Management | EH16: Grand Total
B17: Fire | C17: 1 | CU17: Management | CV17: 7 | CX17: Row Labels | CY17: Count of Employee Type | CZ17: Count of Employee Type2 | DB17: Row Labels | DC17: Count of Employee Type | DD17: Count of Employee Type2 | DR17: Production Dept. | DS17: 153 | ED17: Mar | EG17: 10000 | EH17: 10000
B18: Resigned | C18: 1 | CU18: Grand Total | CV18: 409 | CX18: Permanent | CY18: 22 | CZ18: 0.053789731 | DB18: Female | DC18: 138 | DD18: 0.33740831 | DR18: Quality Dept. | DS18: 126 | ED18: May | EF18: 2500 | EG18: 500 | EH18: 1500 | EP18: Indiract | EQ18: Management | ER18: Grand Total
B19: Grand Total | C19: 409 | CX19: Probation | CY19: 387 | CZ19: 0.94621027 | DB19: Male | DC19: 271 | DD19: 0.66259169 | DR19: Grand Total | DS19: 407 | ED19: Jun | EF19: 44393.833 | EG19: 523 | EH19: 38126.571 | EP19: 6000 | ER19: 12810.811
CU20: Row Labels | CV20: Count of Working status | CX20: Grand Total | CY20: 409 | CZ20: 1 | DB20: Grand Total | DC20: 409 | DD20: 1 | ED20: Jul | EE20: 7396.6 | EF20: 8420.8333 | EG20: 10000 | EH20: 8125.6667 | EP20: 6000 | ER20: 8790.6977
CU21: Active | CV21: 407 | ED21: Aug | EF21: 8116 | EH21: 8116 | EQ21: 10000 | ER21: 20000
CU22: Fire | CV22: 1 | ED22: Sep | EF22: 10000 | EH22: 10000 | EQ22: 30000 | ER22: 30000
B23: Sum of Basic Salary | CU23: Resigned | CV23: 1 | ED23: Nov | EF23: 15816.5 | EH23: 15816.5 | EP23: 16250 | EQ23: 500 | ER23: 11000
B24: 6532800 | CU24: Grand Total | CV24: 409 | ED24: Dec | EE24: 18067.988 | EF24: 5000 | EG24: 10000 | EH24: 17906.645 | EP24: 44393.833 | EQ24: 523 | ER24: 38126.571
DR25: Working status | DS25: All | ED25: Grand Total | EE25: 17865.11 | EF25: 19362.65 | EG25: 6837.1667 | EH25: 17739.792 | EP25: 8420.8333 | EQ25: 10000 | ER25: 8125.6667
EP26: 8116 | ER26: 8116
B27: Average of Basic Salary | DR27: Row Labels | DS27: Count of ID | EP27: 10000 | ER27: 10000
B28: 16011.765 | DR28: Direct | DS28: 378 | EP28: 15816.5 | ER28: 15816.5
DR29: InDirect | DS29: 24 | EP29: 5000 | EQ29: 10000 | ER29: 17906.645
DR30: Management | DS30: 7 | EP30: 18135.542 | EQ30: 10146.143 | ER30: 15997.066
DR31: Grand Total | DS31: 409
DI39: Total Employee | DJ39: Row Labels | DK39: Count of Department
DI40: 409 | DJ40: Administration Dept. | DK40: 4
DJ41: Human Resource Dept. | DK41: 1
DJ42: Packing Dept. | DK42: 93
CU43: Working status | CV43: All | DJ43: PMC & Warehouse Dept. | DK43: 28
DJ44: Product Engineering | DK44: 3
CU45: Row Labels | CV45: Count of ID | DJ45: Production Dept. | DK45: 154
CU46: Assistant Leader | CV46: 5 | DJ46: Quality Dept. | DK46: 126 | EG46: Years (Date of Join) | EH46: (All)
CU47: Assistant Manager | CV47: 2 | DJ47: Grand Total | DK47: 409 | DR47: Working status | DS47: All
CU48: Cleaner | CV48: 2 | EG48: Row Labels | EH48: Sum of Baisc Salary
CU49: Executive | CV49: 15 | DR49: Count of ID | DS49: Column Labels | EG49: Administration Dept. | EH49: 69500
...

Sheet Assignment (2)
A1: Column1
A2: Key Metrics
A3: ​1. Workforce Composition (Headcount)
A4: Total Headcount: What is the total number of employees currently on the payroll?
A5: ​Departmental Split: How many employees are in each department (e.g., Production, Quality, Packing)?
A6: ​Designation Breakdown: Which designations (e.g., Line Operator, Loader) have the highest number of employees?
A7: ​Employee Category: What is the ratio of Management to Direct/Indirect workers?
A8: ​2. Salary & Financial Analysis
A9: ​Total Monthly Payroll: What is the total "Basic Salary" expenditure per month?
A10: ​Average Salary by Department: Which department has the highest and lowest average basic salary?
A11: ​Salary by Designation: What is the average salary for a "Line Operator" versus other roles?
A12: ​Salary vs. Employee Type: How does the salary differ between "Permanent" and "Probation" employees?
... A29: ​Slicers (Filters): Department, Working Status, Gender, and Employee Category to make the dashboard interactiv

Sheet Sheet10

Sheet Sheet6

Sheet Dashboard_Template

Sheet Controls

Sheet Dashboard_Main

Sheet Sheet5

Sheet dataset
A1: SL | B1: ID | C1: Name | D1: Department | E1: Designation | F1: Employee Category | G1: Employee Type | H1: Date of confirmation | I1: Date of Join | J1: Gender | K1: Marital Status | L1: Blood Group | M1: Present Address | N1: Distance | O1: Working status | P1: Baisc Salary
A2: 1 | B2: ACX1 | C2: Shanta Priya | D2: Packing Dept. | E2: Line Operator | F2: Management | G2: Permanent | H2: 45171 | I2: 44991 | J2: Male | K2: Single | L2: B+ | M2: Gazipura 27 | N2: 1km -3km | O2: Active | P2: 10000
A3: =ROW(A1) -> 1 | B3: ACX2 | C3: Md. Abdul Kader | D3: Administration Dept. | E3: Line Operator | F3: Indiract | G3: Probation | H3: 45232 | I3: 45052 | J3: Male | K3: Single | L3: A+ | M3: Gazipura 27 | N3: 1km -3km | O3: Resigned | P3: 2500
A4: =ROW(A2) -> 2 | B4: ACX3 | C4: Md. Sagor Hossain | D4: Production Dept. | E4: Line Operator | F4: Management | G4: Permanent | H4: 45246 | I4: 45066 | J4: Male | K4: Married | L4: O+ | M4: Uttara | N4: 5-10km | O4: Fire | P4: 500
A5: =ROW(A3) -> 3 | B5: ACX4 | C5: Masud Islam Fahim | D5: Quality Dept. | E5: Loader | F5: Indiract | G5: Permanent | H5: 45258 | I5: 45078 | J5: Male | K5: Married | L5: A+ | M5: Bonmala Road | N5: 3km-5km | O5: Active | P5: 10000
A6: =ROW(A4) -> 4 | B6: ACX5 | C6: Md. Manik Mia | D6: Production Dept. | E6: Line Operator | F6: Indiract | G6: Probation | H6: 45269 | I6: 45089 | J6: Male | K6: Single | L6: O+ | M6: Khilkhet | N6: 10-15km | O6: Active | P6: 10000
A7: =ROW(A5) -> 5 | B7: ACX6 | C7: Md. Shajibur Rahaman | D7: Quality Dept. | E7: Line Operator | F7: Indiract | G7: Permanent | H7: 45269 | I7: 45089 | J7: Male | K7: Single | L7: B+ | M7: Gazipura 27 | N7: 1km -3km | O7: Active | P7: 10000
A8: =ROW(A6) -> 6 | B8: ACX7 | C8: Limon | D8: Production Dept. | E8: Line Operator | F8: Indiract | G8: Permanent | H8: 45272 | I8: 45092 | J8: Male | K8: Married | L8: O+ | M8: Gazipura 27 | N8: 1km -3km | O8: Active | P8: 10000
A9: =ROW(A7) -> 7 | B9: ACX8 | C9: Arman Hossen | D9: Quality Dept. | E9: Line Operator | F9: Management | G9: Permanent | H9: 45277 | I9: 45097 | J9: Male | K9: Single | L9: AB+ | M9: Gazipura 27 | N9: 1km -3km | O9: Active | P9: 523
A10: =ROW(A8) -> 8 | B10: ACX9 | C10: Md. Raju Mia | D10: Quality Dept. | E10: Line Operator | F10: Indiract | G10: Permanent | H10: 45277 | I10: 45097 | J10: Male | K10: Single | L10: A+ | M10: Gazipura 27 | N10: 1km -3km | O10: Active | P10: 10000
A11: =ROW(A9) -> 9 | B11: ACX10 | C11: Md. Ammar Hossain | D11: Production Dept. | E11: Line Operator | F11: Indiract | G11: Permanent | H11: 45278 | I11: 45098 | J11: Male | K11: Married | L11: O+ | M11: Gazipura 27 | N11: 1km -3km | O11: Active | P11: 216363
A12: =ROW(A10) -> 10 | B12: ACX11 | C12: Nadim Al Kamal Murad | D12: Production Dept. | E12: Line Operator | F12: Management | G12: Permanent | H12: 45288 | I12: 45108 | J12: Male | K12: Married | L12: O+ | M12: Bonmala Road | N12: 3km-5km | O12: Active | P12: 10000
A13: =ROW(A11) -> 11 | B13: ACX12 | C13: Manik Sharker | D13: Production Dept. | E13: Line Operator | F13: Indiract | G13: Permanent | H13: 45297 | I13: 45117 | J13: Male | K13: Married | L13: AB+ | M13: Gazipura 27 | N13: 1km -3km | O13: Active | P13: 10000
A14: =ROW(A12) -> 12 | B14: ACX13 | C14: Samiul Hoque | D14: Quality Dept. | E14: Line Operator | F14: Indiract | G14: Permanent | H14: 45297 | I14: 45117 | J14: Male | K14: Married | L14: B+ | M14: Gazipur Chowrasta | N14: 5-10km | O14: Active | P14: 525
... A410: =ROW(A408) -> 408 | B410: ACX409 | C410: Md. Abdullah Al Ripon | D410: Quality Dept. | E410: Manager | F410: Indiract | G410: Probation | H410: 45594 | I410: 45414 | J410: Male | K410: Married | L410: O+ | M410: Kaliakoir | N410: 20km-30km | O410: Active | P410: 30000

Sheet MasterDatabse
A1: SL | B1: ID | C1: Name | D1: Department | E1: Designation | F1: Employee Category | G1: Employee Type | H1: Date of confirmation | I1: Date of Join | J1: Gender | K1: Marital Status | L1: Blood Group | M1: Present Address | N1: Distance | O1: Working status | P1: Basic Salary | Q1: Join Month | R1: Status Group
A2: 1 | B2: ACX1 | C2: Shanta Priya | D2: Packing Dept. | E2: Line Operator | F2: Management | G2: Permanent | H2: 45171 | I2: 44991 | J2: Male | K2: Single | L2: B+ | M2: Gazipura 27 | N2: 1km -3km | O2: Active | P2: 10000 | Q2: =TEXT(tblHR[[#This Row],[Date of Join]],"mmm-yy") -> Mar-23 | R2: Join Month
A3: 2 | B3: ACX2 | C3: Md. Abdul Kader | D3: Administration Dept. | E3: Line Operator | F3: InDirect | G3: Probation | H3: 45232 | I3: 45052 | J3: Male | K3: Single | L3: A+ | M3: Gazipura 27 | N3: 1km -3km | O3: Resigned | P3: 2500 | Q3: =TEXT(tblHR[[#This Row],[Date of Join]],"mmm-yy") -> May-23 | R3: =IF(tblHR[[#This Row],[Working status]]="Active","Active","Exit") -> Exit
A4: 3 | B4: ACX3 | C4: Md. Sagor Hossain | D4: Production Dept. | E4: Line Operator | F4: Management | G4: Permanent | H4: 45246 | I4: 45066 | J4: Male | K4: Married | L4: O+ | M4: Uttara | N4: 5-10km | O4: Fire | P4: 500 | Q4: =TEXT(tblHR[[#This Row],[Date of Join]],"mmm-yy") -> May-23 | R4: =IF(tblHR[[#This Row],[Working status]]="Active","Active","Exit") -> Exit
A5: 4 | B5: ACX4 | C5: Masud Islam Fahim | D5: Quality Dept. | E5: Loader | F5: InDirect | G5: Permanent | H5: 45258 | I5: 45078 | J5: Male | K5: Married | L5: A+ | M5: Bonmala Road | N5: 3km-5km | O5: Active | P5: 10000 | Q5: =TEXT(tblHR[[#This Row],[Date of Join]],"mmm-yy") -> Jun-23 | R5: =IF(tblHR[[#This Row],[Working status]]="Active","Active","Exit") -> Active
A6: 5 | B6: ACX5 | C6: Md. Manik Mia | D6: Production Dept. | E6: Line Operator | F6: InDirect | G6: Probation | H6: 45269 | I6: 45089 | J6: Male | K6: Single | L6: O+ | M6: Khilkhet | N6: 10-15km | O6: Active | P6: 10000 | Q6: =TEXT(tblHR[[#This Row],[Date of Join]],"mmm-yy") -> Jun-23 | R6: =IF(tblHR[[#This Row],[Working status]]="Active","Active","Exit") -> Active
A7: 6 | B7: ACX6 | C7: Md. Shajibur Rahaman | D7: Quality Dept. | E7: Line Operator | F7: InDirect | G7: Permanent | H7: 45269 | I7: 45089 | J7: Male | K7: Single | L7: B+ | M7: Gazipura 27 | N7: 1km -3km | O7: Active | P7: 10000 | Q7: =TEXT(tblHR[[#This Row],[Date of Join]],"mmm-yy") -> Jun-23 | R7: =IF(tblHR[[#This Row],[Working status]]="Active","Active","Exit") -> Active
A8: 7 | B8: ACX7 | C8: Limon | D8: Production Dept. | E8: Line Operator | F8: InDirect | G8: Permanent | H8: 45272 | I8: 45092 | J8: Male | K8: Married | L8: O+ | M8: Gazipura 27 | N8: 1km -3km | O8: Active | P8: 10000 | Q8: =TEXT(tblHR[[#This Row],[Date of Join]],"mmm-yy") -> Jun-23 | R8: =IF(tblHR[[#This Row],[Working status]]="Active","Active","Exit") -> Active
A9: 8 | B9: ACX8 | C9: Arman Hossen | D9: Quality Dept. | E9: Line Operator | F9: Management | G9: Permanent | H9: 45277 | I9: 45097 | J9: Male | K9: Single | L9: AB+ | M9: Gazipura 27 | N9: 1km -3km | O9: Active | P9: 523 | Q9: =TEXT(tblHR[[#This Row],[Date of Join]],"mmm-yy") -> Jun-23 | R9: =IF(tblHR[[#This Row],[Working status]]="Active","Active","Exit") -> Active
A10: 9 | B10: ACX9 | C10: Md. Raju Mia | D10: Quality Dept. | E10: Line Operator | F10: InDirect | G10: Permanent | H10: 45277 | I10: 45097 | J10: Male | K10: Single | L10: A+ | M10: Gazipura 27 | N10: 1km -3km | O10: Active | P10: 10000 | Q10: =TEXT(tblHR[[#This Row],[Date of Join]],"mmm-yy") -> Jun-23 | R10: =IF(tblHR[[#This Row],[Working status]]="Active","Active","Exit") -> Active
A11: 10 | B11: ACX10 | C11: Md. Ammar Hossain | D11: Production Dept. | E11: Line Operator | F11: InDirect | G11: Permanent | H11: 45278 | I11: 45098 | J11: Male | K11: Married | L11: O+ | M11: Gazipura 27 | N11: 1km -3km | O11: Active | P11: 216363 | Q11: =TEXT(tblHR[[#This Row],[Date of Join]],"mmm-yy") -> Jun-23 | R11: =IF(tblHR[[#This Row],[Working status]]="Active","Active","Exit") -> Active
A12: 11 | B12: ACX11 | C12: Nadim Al Kamal Murad | D12: Production Dept. | E12: Line Operator | F12: Management | G12: Permanent | H12: 45288 | I12: 45108 | J12: Male | K12: Married | L12: O+ | M12: Bonmala Road | N12: 3km-5km | O12: Active | P12: 10000 | Q12: =TEXT(tblHR[[#This Row],[Date of Join]],"mmm-yy") -> Jul-23 | R12: =IF(tblHR[[#This Row],[Working status]]="Active","Active","Exit") -> Active
A13: 12 | B13: ACX12 | C13: Manik Sharker | D13: Production Dept. | E13: Line Operator | F13: InDirect | G13: Permanent | H13: 45297 | I13: 45117 | J13: Male | K13: Married | L13: AB+ | M13: Gazipura 27 | N13: 1km -3km | O13: Active | P13: 10000 | Q13: =TEXT(tblHR[[#This Row],[Date of Join]],"mmm-yy") -> Jul-23 | R13: =IF(tblHR[[#This Row],[Working status]]="Active","Active","Exit") -> Active
A14: 13 | B14: ACX13 | C14: Samiul Hoque | D14: Quality Dept. | E14: Line Operator | F14: InDirect | G14: Permanent | H14: 45297 | I14: 45117 | J14: Male | K14: Married | L14: B+ | M14: Gazipur Chowrasta | N14: 5-10km | O14: Active | P14: 525 | Q14: =TEXT(tblHR[[#This Row],[Date of Join]],"mmm-yy") -> Jul-23 | R14: =IF(tblHR[[#This Row],[Working status]]="Active","Active","Exit") -> Active
... A410: 409 | B410: ACX409 | C410: Md. Abdullah Al Ripon | D410: Quality Dept. | E410: Manager | F410: InDirect | G410: Probation | H410: 45594 | I410: 45414 | J410: Male | K410: Married | L410: O+ | M410: Kaliakoir | N410: 20km-30km | O410: Active | P410: 30000 | Q410: =TEXT(tblHR[[#This Row],[Date of Join]],"mmm-yy") -> May-24 | R410: =IF(tblHR[[#This Row],[Working status]]="Active","Active","Exit") -> Active

Sheet Dashboard_1
K2: Last Updated
K3: =TEXT(TODAY(),"dd-mmm-yyyy") -> 18-Apr-2026
B10: Total Employees | D10: Active Employees | F10: Total Payroll | H10: Average Salary | J10: Probation % | L10: Female %
B11: =IFERROR(GETPIVOTDATA("Employees Count",Master_Pivot!$P$3),0) -> 21 | D11: =IFERROR(GETPIVOTDATA("Employees Count",Master_Pivot!$AN$3,"Working status","Active"),0) -> 21 | F11: =IFERROR(GETPIVOTDATA("Total Payroll",Master_Pivot!$S$3),0) -> 370626 | H11: =IFERROR(GETPIVOTDATA("Average Salary",Master_Pivot!$Y$3),0) -> 18531.3 | J11: =IFERROR(GETPIVOTDATA("Employees Count",Master_Pivot!$M$3,"Employee Type","Probation")/GETPIVOTDATA("Employees Count",Master_Pivot!$P$3),0) -> 0 | L11: =IFERROR(GETPIVOTDATA("Employees Count",Master_Pivot!$I$3,"Gender","Female")/GETPIVOTDATA("Employees Count",Master_Pivot!$P$3),0) -> 0.047619048

Sheet Dashboard_Detail
